Workbook

Sheet 설정값
A1: 고양이가 인간을 키움 — 밸런스 초안 v0.1
A2: 파란 글씨 = 바꿔도 되는 숫자. 여기만 고치면 '일터 효율', '하루 시뮬레이션' 시트가 자동으로 다시 계산됩니다. 모든 숫자는 테스트용 초안(Claude 제안)이며 프로토타입으로 조정 예정.
A4: ① 일터
A5: 일터 | B5: 근무 시간(분) | C5: 기본 츄르(1회) | D5: 피로 증가(1회) | E5: 시작 자리 수 | F5: 메모
A6: 편의점 | B6: 30 | C6: 30 | D6: 15 | E6: 1 | F6: 자주 켜는 사람용
A7: 회사 | B7: 120 | C7: 100 | D7: 30 | E7: 1 | F7: 점심·퇴근길용
A8: 공사장 | B8: 480 | C8: 300 | D8: 60 | E8: 1 | F8: 자기 전·출근 전용
A10: ② 집사 공통 규칙
A11: 항목 | B11: 값 | F11: 설명
A12: 적성 보너스 | B12: 0.5 | F12: 맞는 일터에 보내면 수입 +50% (기획서)
A13: 피로 상한 | B13: 100 | F13: 피로도 0~100
A14: 효율 저하 시작 피로 | B14: 70 | F14: 이 이상이면 수입 감소
A15: 효율 저하 비율 | B15: 0.3 | F15: 피로 70 이상일 때 수입 -30%
A16: 출근 거부 피로 | B16: 90 | F16: 이 이상이면 일터 배치 불가
A17: 자연 회복(시간당, 집에 있을 때) | B17: 10 | F17: 근무 중에는 회복 없음
A18: 호감도 상한 | B18: 100
A19: 호감도 단계 간격 | B19: 20 | F19: 20마다 1단계 → 냄새 노트 한 줄 해금
A20: 호감도 단계당 수입 보너스 | B20: 0.05 | F20: 5단계 = +25%
A21: 쓰다듬기 호감도 | B21: 2 | F21: 집사당 하루 3회까지
A22: 쓰다듬기 하루 횟수 | B22: 3
A24: ③ 꾹꾹이 미니게임
A25: 결과 | B25: 판정 정확도 이상 | C25: 피로 회복 | D25: 호감도 | E25: 보너스 츄르 | F25: 설명
A26: 적당히 | B26: 0 | C26: 30 | D26: 2 | E26: 0 | F26: 실패 없음 — 최소 보상
A27: 잘함 | B27: 0.6 | C27: 50 | D27: 5 | E27: 0
A28: 완벽 | B28: 0.9 | C28: 100 | D28: 10 | E28: 20 | F28: 피로 전부 회복 + 녹아내림 연출
A30: 박자 설정 | B30: 값 | F30: 설명
A31: 게임 길이(초) | B31: 40 | F31: 기획서
A32: 박자 간격(초) | B32: 0.6 | F32: 꾹-꾹 한 번 = 0.6초 (BPM 100)
A33: '정확' 판정 범위(±초) | B33: 0.12 | F33: 이 안에 누르면 정확
A34: '좋음' 판정 범위(±초) | B34: 0.25 | F34: 정확=1점, 좋음=0.5점, 그 밖=0점
A35: 총 박자 수 | B35: =INT(B31/B32) -> 66 | F35: 자동 계산
A37: ④ 인력사무소 뽑기
A38: 항목 | B38: 값 | F38: 설명
A39: 뽑기 1회 가격(츄르) | B39: 300 | F39: 가장 중요한 손잡이 — 너무 빨리 모이면 400~500으로
A40: 일반 확률 | B40: 0.85 | F40: 등급 안에서는 집사별 균등
A41: 레어 확률 | B41: 0.13
A42: 전설 확률 | B42: 0.02
A43: 확률 합계 확인 | B43: =B40+B41+B42 -> 1 | F43: 반드시 100%
A44: 전설 천장(회) | B44: 50 | F44: 50회 안에 전설 확정 — 지인 테스트 체감용 제안
A45: 중복 시 호감도 | B45: 20 | F45: 꽝 없음 (기획서)
...

Sheet 일터 효율
A1: 일터별 효율 — 자동 계산
A2: 자주 켤수록 시간당 이득이 크고, 오래 비울수록 한 번에 많이 받는 구조인지 확인하는 표
A4: 일터 | B4: 근무 시간(분) | C4: 1회 츄르 | D4: 시간당 츄르 | E4: 적성 시 1회 | F4: 적성 시 시간당 | G4: 피로 70+ 1회 | H4: 연속 출근 가능(회) | I4: 츄르 1개당 피로
A5: =설정값!A6 -> 편의점 | B5: =설정값!B6 -> 30 | C5: =설정값!C6 -> 30 | D5: =C5/(B5/60) -> 60 | E5: =C5*(1+설정값!$B$12) -> 45 | F5: =E5/(B5/60) -> 90 | G5: =C5*(1-설정값!$B$15) -> 21 | H5: =INT((설정값!$B$16-1)/설정값!D6)+1 -> 6 | I5: =설정값!D6/C5 -> 0.5
A6: =설정값!A7 -> 회사 | B6: =설정값!B7 -> 120 | C6: =설정값!C7 -> 100 | D6: =C6/(B6/60) -> 50 | E6: =C6*(1+설정값!$B$12) -> 150 | F6: =E6/(B6/60) -> 75 | G6: =C6*(1-설정값!$B$15) -> 70 | H6: =INT((설정값!$B$16-1)/설정값!D7)+1 -> 3 | I6: =설정값!D7/C6 -> 0.3
A7: =설정값!A8 -> 공사장 | B7: =설정값!B8 -> 480 | C7: =설정값!C8 -> 300 | D7: =C7/(B7/60) -> 37.5 | E7: =C7*(1+설정값!$B$12) -> 450 | F7: =E7/(B7/60) -> 56.25 | G7: =C7*(1-설정값!$B$15) -> 210 | H7: =INT((설정값!$B$16-1)/설정값!D8)+1 -> 2 | I7: =설정값!D8/C7 -> 0.2
A9: 연속 출근 가능 = 피로 0에서 시작해 자연 회복 없이 몇 번 연달아 보낼 수 있는지. 꾹꾹이로 이 제한을 풀어주는 게 핵심 고리.

Sheet 하루 시뮬레이션
A1: 플레이 유형별 하루 수입과 수집 속도
A2: 파란 칸(하루 근무 횟수, 적성 비율)은 가정값. 노란 칸이 핵심 결과 — 뽑기가 너무 빠르거나 느린지 판단.
A4: 항목 | B4: 첫날 (집사 1~2명) | C4: 자주 켜는 사람 | D4: 가끔 켜는 사람 | E4: 설명
A5: 편의점 근무 횟수/일 | B5: 4 | C5: 6 | D5: 0 | E5: 30분마다 들어와서 다시 보냄
A6: 회사 근무 횟수/일 | B6: 1 | C6: 3 | D6: 1 | E6: 점심·퇴근길
A7: 공사장 근무 횟수/일 | B7: 1 | C7: 1 | D7: 2 | E7: 밤새·출근 시간
A8: 적성 맞춘 비율 | B8: 0.5 | C8: 0.5 | D8: 0.5 | E8: 절반 정도는 적성에 맞게 배치한다고 가정
A9: 하루 츄르(근무) | B9: =(B5*설정값!$C$6+B6*설정값!$C$7+B7*설정값!$C$8)*(1+설정값!$B$12*B8) -> 650 | C9: =(C5*설정값!$C$6+C6*설정값!$C$7+C7*설정값!$C$8)*(1+설정값!$B$12*C8) -> 975 | D9: =(D5*설정값!$C$6+D6*설정값!$C$7+D7*설정값!$C$8)*(1+설정값!$B$12*D8) -> 875 | E9: 피로 페널티·호감 보너스 제외
A10: 유료 뽑기 횟수/일 | B10: =B9/설정값!$B$39 -> 2.1666667 | C10: =C9/설정값!$B$39 -> 3.25 | D10: =D9/설정값!$B$39 -> 2.9166667
A11: 총 뽑기 횟수/일 | B11: =B10+설정값!$B$46 -> 3.1666667 | C11: =C10+설정값!$B$46 -> 4.25 | D11: =D10+설정값!$B$46 -> 3.9166667 | E11: 무료 이용권 포함
A12: 레어 하나 나오는 데 걸리는 날 | B12: =(1/설정값!$B$41)/B11 -> 2.4291498 | C12: =(1/설정값!$B$41)/C11 -> 1.8099548 | D12: =(1/설정값!$B$41)/D11 -> 1.9639935 | E12: 기대값
A13: 전설 기대 일수(천장 포함) | B13: =((1-(1-설정값!$B$42)^설정값!$B$44)/설정값!$B$42)/B11 -> 10.039426 | C13: =((1-(1-설정값!$B$42)^설정값!$B$44)/설정값!$B$42)/C11 -> 7.4803567 | D13: =((1-(1-설정값!$B$42)^설정값!$B$44)/설정값!$B$42)/D11 -> 8.1169828 | E13: 천장 덕분에 확률만으로 본 평균(50회)보다 빠름
A14: 전설 최대 일수(천장) | B14: =설정값!$B$44/B11 -> 15.789474 | C14: =설정값!$B$44/C11 -> 11.764706 | D14: =설정값!$B$44/D11 -> 12.765957 | E14: 아무리 운이 나빠도 이 안에
A15: 8종 도감 완성 최대(일) | B15: =B14 -> 15.789474 | C15: =C14 -> 11.764706 | D15: =D14 -> 12.765957 | E15: 전설이 사실상 마지막 퍼즐 — 천장 기준
A17: 판단 기준(제안): 자주 켜는 사람이 하루 3~5회 뽑고, 일주일 테스트 안에 전설을 볼 수도 있는 정도 → 지인 테스트에서 '한 번 더 켤 이유'가 생김. 출시 땐 가격을 올려 속도를 늦춤.
A18: 주의: 일터 자리(시작 1자리)가 동시에 보낼 수 있는 인원을 제한하므로, 위 근무 횟수는 그 안에서 현실적인 값으로 잡았음.
